INFO 09-05 15:50:08 [__init__.py:36] Available plugins for group vllm.platform_plugins:
INFO 09-05 15:50:08 [__init__.py:38] - ascend -> vllm_ascend:register
INFO 09-05 15:50:08 [__init__.py:41] All plugins in this group will be loaded. Set `VLLM_PLUGINS` to control which plugins to load.
INFO 09-05 15:50:08 [__init__.py:232] Platform plugin ascend is activated
WARNING 09-05 15:50:09 [_custom_ops.py:20] Failed to import from vllm._C with ModuleNotFoundError("No module named 'vllm._C'")
INFO 09-05 15:50:10 [importing.py:63] Triton not installed or not compatible; certain GPU-related functions will not be available.
WARNING 09-05 15:50:11 [registry.py:464] Model architecture DeepSeekMTPModel is already registered, and will be overwritten by the new model class vllm_ascend.models.deepseek_mtp:CustomDeepSeekMTP.
WARNING 09-05 15:50:11 [registry.py:464] Model architecture Qwen2VLForConditionalGeneration is already registered, and will be overwritten by the new model class vllm_ascend.models.qwen2_vl:AscendQwen2VLForConditionalGeneration.
WARNING 09-05 15:50:11 [registry.py:464] Model architecture Qwen2_5_VLForConditionalGeneration is already registered, and will be overwritten by the new model class vllm_ascend.models.qwen2_5_vl:AscendQwen2_5_VLForConditionalGeneration.
WARNING 09-05 15:50:11 [registry.py:464] Model architecture DeepseekV2ForCausalLM is already registered, and will be overwritten by the new model class vllm_ascend.models.deepseek_v2:CustomDeepseekV2ForCausalLM.
WARNING 09-05 15:50:11 [registry.py:464] Model architecture DeepseekV3ForCausalLM is already registered, and will be overwritten by the new model class vllm_ascend.models.deepseek_v3:CustomDeepseekV3ForCausalLM.
WARNING 09-05 15:50:11 [registry.py:464] Model architecture Qwen3MoeForCausalLM is already registered, and will be overwritten by the new model class vllm_ascend.models.qwen3_moe:CustomQwen3MoeForCausalLM.
WARNING 09-05 15:50:11 [registry.py:464] Model architecture Qwen3ForCausalLM is already registered, and will be overwritten by the new model class vllm_ascend.models.qwen3:CustomQwen3ForCausalLM.
INFO 09-05 15:50:11 [utils.py:326] non-default args: {'model': '/mnt/weight/deepseekv3-lite-base-latest', 'trust_remote_code': True, 'max_model_len': 4096, 'tensor_parallel_size': 2, 'context_parallel_size': 4, 'enable_sequence_parallel': True, 'enable_expert_parallel': True, 'block_size': 128, 'enable_prefix_caching': False, 'max_num_batched_tokens': 1024, 'disable_log_stats': True, 'enforce_eager': True, 'enable_chunked_prefill': True, 'additional_config': {'ascend_scheduler_config': {'enabled': True}}}
INFO 09-05 15:50:11 [config.py:240] Replacing legacy 'type' key with 'rope_type'
INFO 09-05 15:50:19 [__init__.py:742] Resolved architecture: DeepseekV3ForCausalLM
INFO 09-05 15:50:19 [__init__.py:1774] Using max model len 4096
INFO 09-05 15:50:19 [config.py:240] Replacing legacy 'type' key with 'rope_type'
INFO 09-05 15:50:19 [scheduler.py:222] Chunked prefill is enabled with max_num_batched_tokens=1024.
INFO 09-05 15:50:19 [platform.py:156] Compilation disabled, using eager mode by default
[1;36m(EngineCore_0 pid=285866)[0;0m INFO 09-05 15:50:20 [core.py:644] Waiting for init message from front-end.
[1;36m(EngineCore_0 pid=285866)[0;0m INFO 09-05 15:50:20 [core.py:74] Initializing a V1 LLM engine (v0.1.dev8800+g376d98484.d20250901) with config: model='/mnt/weight/deepseekv3-lite-base-latest', speculative_config=None, tokenizer='/mnt/weight/deepseekv3-lite-base-latest', skip_tokenizer_init=False, tokenizer_mode=auto, revision=None, override_neuron_config={}, tokenizer_revision=None, trust_remote_code=True, dtype=torch.float16, max_seq_len=4096, download_dir=None, load_format=auto, tensor_parallel_size=2, pipeline_parallel_size=1, disable_custom_all_reduce=True, quantization=None, enforce_eager=True, kv_cache_dtype=auto, device_config=npu, decoding_config=DecodingConfig(backend='auto', disable_fallback=False, disable_any_whitespace=False, disable_additional_properties=False, reasoning_backend=''), observability_config=ObservabilityConfig(show_hidden_metrics_for_version=None, otlp_traces_endpoint=None, collect_detailed_traces=None), seed=0, served_model_name=/mnt/weight/deepseekv3-lite-base-latest, enable_prefix_caching=False, chunked_prefill_enabled=False, use_async_output_proc=True, pooler_config=None, compilation_config={"level":0,"debug_dump_path":"","cache_dir":"","backend":"","custom_ops":["all"],"splitting_ops":null,"use_inductor":true,"compile_sizes":[],"inductor_compile_config":{"enable_auto_functionalized_v2":false},"inductor_passes":{},"cudagraph_mode":0,"use_cudagraph":true,"cudagraph_num_of_warmups":0,"cudagraph_capture_sizes":[],"cudagraph_copy_inputs":false,"full_cuda_graph":false,"pass_config":{},"max_capture_size":0,"local_cache_dir":null}
[1;36m(EngineCore_0 pid=285866)[0;0m WARNING 09-05 15:50:20 [multiproc_worker_utils.py:273] Reducing Torch parallelism from 640 threads to 1 to avoid unnecessary CPU contention. Set OMP_NUM_THREADS in the external environment to tune this value as needed.
[1;36m(EngineCore_0 pid=285866)[0;0m INFO 09-05 15:50:20 [shm_broadcast.py:289] vLLM message queue communication handle: Handle(local_reader_ranks=[0, 1, 2, 3, 4, 5, 6, 7], buffer_handle=(8, 16777216, 10, 'psm_267f86de'), local_subscribe_addr='ipc:///tmp/5fb68f95-a5b0-4669-b90f-e60857f302ca', remote_subscribe_addr=None, remote_addr_ipv6=False)
[1;36m(EngineCore_0 pid=285866)[0;0m [1;36m(VllmWorker TP1 pid=285878)[0;0m INFO 09-05 15:50:30 [shm_broadcast.py:289] vLLM message queue communication handle: Handle(local_reader_ranks=[0], buffer_handle=(1, 10485760, 10, 'psm_729933ae'), local_subscribe_addr='ipc:///tmp/39504549-3354-496c-ba69-d994cb7033d5', remote_subscribe_addr=None, remote_addr_ipv6=False)
[1;36m(EngineCore_0 pid=285866)[0;0m [1;36m(VllmWorker TP1 pid=285898)[0;0m INFO 09-05 15:50:30 [shm_broadcast.py:289] vLLM message queue communication handle: Handle(local_reader_ranks=[0], buffer_handle=(1, 10485760, 10, 'psm_1e3ac0cc'), local_subscribe_addr='ipc:///tmp/77ce9e01-1d19-4a8b-a5a8-23ca9c27ed27', remote_subscribe_addr=None, remote_addr_ipv6=False)
[1;36m(EngineCore_0 pid=285866)[0;0m [1;36m(VllmWorker TP1 pid=285898)[0;0m ERROR 09-05 15:50:30 [multiproc_executor.py:567] WorkerProc failed to start.
[1;36m(EngineCore_0 pid=285866)[0;0m [1;36m(VllmWorker TP1 pid=285898)[0;0m ERROR 09-05 15:50:30 [multiproc_executor.py:567] Traceback (most recent call last):
[1;36m(EngineCore_0 pid=285866)[0;0m [1;36m(VllmWorker TP1 pid=285898)[0;0m ERROR 09-05 15:50:30 [multiproc_executor.py:567]   File "/home/vllm/vllm/v1/executor/multiproc_executor.py", line 541, in worker_main
[1;36m(EngineCore_0 pid=285866)[0;0m [1;36m(VllmWorker TP1 pid=285898)[0;0m ERROR 09-05 15:50:30 [multiproc_executor.py:567]     worker = WorkerProc(*args, **kwargs)
[1;36m(EngineCore_0 pid=285866)[0;0m [1;36m(VllmWorker TP1 pid=285898)[0;0m ERROR 09-05 15:50:30 [multiproc_executor.py:567]              ^^^^^^^^^^^^^^^^^^^^^^^^^^^
[1;36m(EngineCore_0 pid=285866)[0;0m [1;36m(VllmWorker TP1 pid=285898)[0;0m ERROR 09-05 15:50:30 [multiproc_executor.py:567]   File "/home/vllm/vllm/v1/executor/multiproc_executor.py", line 409, in __init__
[1;36m(EngineCore_0 pid=285866)[0;0m [1;36m(VllmWorker TP1 pid=285898)[0;0m ERROR 09-05 15:50:30 [multiproc_executor.py:567]     self.worker.init_device()
[1;36m(EngineCore_0 pid=285866)[0;0m [1;36m(VllmWorker TP1 pid=285898)[0;0m ERROR 09-05 15:50:30 [multiproc_executor.py:567]   File "/home/vllm/vllm/worker/worker_base.py", line 603, in init_device
[1;36m(EngineCore_0 pid=285866)[0;0m [1;36m(VllmWorker TP1 pid=285898)[0;0m ERROR 09-05 15:50:30 [multiproc_executor.py:567]     self.worker.init_device()  # type: ignore
[1;36m(EngineCore_0 pid=285866)[0;0m [1;36m(VllmWorker TP1 pid=285898)[0;0m ERROR 09-05 15:50:30 [multiproc_executor.py:567]     ^^^^^^^^^^^^^^^^^^^^^^^^^
[1;36m(EngineCore_0 pid=285866)[0;0m [1;36m(VllmWorker TP1 pid=285898)[0;0m ERROR 09-05 15:50:30 [multiproc_executor.py:567]   File "/home/vllm-ascend-origin/vllm_ascend/worker/worker_v1.py", line 144, in init_device
[1;36m(EngineCore_0 pid=285866)[0;0m [1;36m(VllmWorker TP1 pid=285898)[0;0m ERROR 09-05 15:50:30 [multiproc_executor.py:567]     device = self._init_device()
[1;36m(EngineCore_0 pid=285866)[0;0m [1;36m(VllmWorker TP1 pid=285898)[0;0m ERROR 09-05 15:50:30 [multiproc_executor.py:567]              ^^^^^^^^^^^^^^^^^^^
[1;36m(EngineCore_0 pid=285866)[0;0m [1;36m(VllmWorker TP1 pid=285898)[0;0m ERROR 09-05 15:50:30 [multiproc_executor.py:567]   File "/home/vllm-ascend-origin/vllm_ascend/worker/worker_v1.py", line 134, in _init_device
[1;36m(EngineCore_0 pid=285866)[0;0m [1;36m(VllmWorker TP1 pid=285898)[0;0m ERROR 09-05 15:50:30 [multiproc_executor.py:567]     NPUPlatform.set_device(device)
[1;36m(EngineCore_0 pid=285866)[0;0m [1;36m(VllmWorker TP1 pid=285898)[0;0m ERROR 09-05 15:50:30 [multiproc_executor.py:567]   File "/home/vllm-ascend-origin/vllm_ascend/platform.py", line 97, in set_device
[1;36m(EngineCore_0 pid=285866)[0;0m [1;36m(VllmWorker TP1 pid=285898)[0;0m ERROR 09-05 15:50:30 [multiproc_executor.py:567]     torch.npu.set_device(device)
[1;36m(EngineCore_0 pid=285866)[0;0m [1;36m(VllmWorker TP1 pid=285898)[0;0m ERROR 09-05 15:50:30 [multiproc_executor.py:567]   File "/usr/local/python3.11.10/lib/python3.11/site-packages/torch_npu/npu/utils.py", line 64, in set_device
[1;36m(EngineCore_0 pid=285866)[0;0m [1;36m(VllmWorker TP1 pid=285898)[0;0m ERROR 09-05 15:50:30 [multiproc_executor.py:567]     torch_npu._C._npu_setDevice(device_id)
[1;36m(EngineCore_0 pid=285866)[0;0m [1;36m(VllmWorker TP1 pid=285898)[0;0m ERROR 09-05 15:50:30 [multiproc_executor.py:567] RuntimeError: ExchangeDevice:build/CMakeFiles/torch_npu.dir/compiler_depend.ts:202 NPU function error: c10_npu::SetDevice(device), error code is 107001
[1;36m(EngineCore_0 pid=285866)[0;0m [1;36m(VllmWorker TP1 pid=285898)[0;0m ERROR 09-05 15:50:30 [multiproc_executor.py:567] [ERROR] 2025-09-05-15:50:30 (PID:285898, Device:0, RankID:-1) ERR00100 PTA call acl api failed
[1;36m(EngineCore_0 pid=285866)[0;0m [1;36m(VllmWorker TP1 pid=285898)[0;0m ERROR 09-05 15:50:30 [multiproc_executor.py:567] [Error]: Invalid device ID.
[1;36m(EngineCore_0 pid=285866)[0;0m [1;36m(VllmWorker TP1 pid=285898)[0;0m ERROR 09-05 15:50:30 [multiproc_executor.py:567]         Check whether the device ID is valid.
[1;36m(EngineCore_0 pid=285866)[0;0m [1;36m(VllmWorker TP1 pid=285898)[0;0m ERROR 09-05 15:50:30 [multiproc_executor.py:567] EE1001: [PID: 285898] 2025-09-05-15:50:30.927.041 The argument is invalid.Reason: Set visible device failed, invalid device=5, input visible devices:0,1,2,3
[1;36m(EngineCore_0 pid=285866)[0;0m [1;36m(VllmWorker TP1 pid=285898)[0;0m ERROR 09-05 15:50:30 [multiproc_executor.py:567]         Solution: 1.Check the input parameter range of the function. 2.Check the function invocation relationship.
[1;36m(EngineCore_0 pid=285866)[0;0m [1;36m(VllmWorker TP1 pid=285898)[0;0m ERROR 09-05 15:50:30 [multiproc_executor.py:567]         TraceBack (most recent call last):
[1;36m(EngineCore_0 pid=285866)[0;0m [1;36m(VllmWorker TP1 pid=285898)[0;0m ERROR 09-05 15:50:30 [multiproc_executor.py:567]         rtSetDevice execute failed, reason=[device id error][FUNC:FuncErrorReason][FILE:error_message_manage.cc][LINE:53]
[1;36m(EngineCore_0 pid=285866)[0;0m [1;36m(VllmWorker TP1 pid=285898)[0;0m ERROR 09-05 15:50:30 [multiproc_executor.py:567]         open device 5 failed, runtime result = 107001.[FUNC:ReportCallError][FILE:log_inner.cpp][LINE:161]
[1;36m(EngineCore_0 pid=285866)[0;0m [1;36m(VllmWorker TP1 pid=285898)[0;0m ERROR 09-05 15:50:30 [multiproc_executor.py:567] 
[1;36m(EngineCore_0 pid=285866)[0;0m [1;36m(VllmWorker TP0 pid=285893)[0;0m INFO 09-05 15:50:31 [shm_broadcast.py:289] vLLM message queue communication handle: Handle(local_reader_ranks=[0], buffer_handle=(1, 10485760, 10, 'psm_2c9f3bf5'), local_subscribe_addr='ipc:///tmp/18b9fa39-937b-4c83-9f79-3acffc27d136', remote_subscribe_addr=None, remote_addr_ipv6=False)
[1;36m(EngineCore_0 pid=285866)[0;0m ERROR 09-05 15:50:32 [multiproc_executor.py:567] WorkerProc failed to start.
[1;36m(EngineCore_0 pid=285866)[0;0m ERROR 09-05 15:50:32 [multiproc_executor.py:567] Traceback (most recent call last):
[1;36m(EngineCore_0 pid=285866)[0;0m ERROR 09-05 15:50:32 [multiproc_executor.py:567]   File "/home/vllm/vllm/v1/executor/multiproc_executor.py", line 541, in worker_main
[1;36m(EngineCore_0 pid=285866)[0;0m ERROR 09-05 15:50:32 [multiproc_executor.py:567]     worker = WorkerProc(*args, **kwargs)
[1;36m(EngineCore_0 pid=285866)[0;0m ERROR 09-05 15:50:32 [multiproc_executor.py:567]              ^^^^^^^^^^^^^^^^^^^^^^^^^^^
[1;36m(EngineCore_0 pid=285866)[0;0m ERROR 09-05 15:50:32 [multiproc_executor.py:567]   File "/home/vllm/vllm/v1/executor/multiproc_executor.py", line 387, in __init__
[1;36m(EngineCore_0 pid=285866)[0;0m ERROR 09-05 15:50:32 [multiproc_executor.py:567]     wrapper.init_worker(all_kwargs)
[1;36m(EngineCore_0 pid=285866)[0;0m ERROR 09-05 15:50:32 [multiproc_executor.py:567]   File "/home/vllm/vllm/worker/worker_base.py", line 592, in init_worker
[1;36m(EngineCore_0 pid=285866)[0;0m ERROR 09-05 15:50:32 [multiproc_executor.py:567]     self.worker = worker_class(**kwargs)
[1;36m(EngineCore_0 pid=285866)[0;0m ERROR 09-05 15:50:32 [multiproc_executor.py:567]                   ^^^^^^^^^^^^^^^^^^^^^^
[1;36m(EngineCore_0 pid=285866)[0;0m ERROR 09-05 15:50:32 [multiproc_executor.py:567]   File "/home/vllm-ascend-origin/vllm_ascend/worker/worker_v1.py", line 76, in __init__
[1;36m(EngineCore_0 pid=285866)[0;0m ERROR 09-05 15:50:32 [multiproc_executor.py:567]     init_ascend_soc_version()
[1;36m(EngineCore_0 pid=285866)[0;0m ERROR 09-05 15:50:32 [multiproc_executor.py:567]   File "/home/vllm-ascend-origin/vllm_ascend/utils.py", line 512, in init_ascend_soc_version
[1;36m(EngineCore_0 pid=285866)[0;0m ERROR 09-05 15:50:32 [multiproc_executor.py:567]     soc_version = torch_npu.npu.get_soc_version()
[1;36m(EngineCore_0 pid=285866)[0;0m ERROR 09-05 15:50:32 [multiproc_executor.py:567]                   ^^^^^^^^^^^^^^^^^^^^^^^^^^^^^^^
[1;36m(EngineCore_0 pid=285866)[0;0m ERROR 09-05 15:50:32 [multiproc_executor.py:567]   File "/usr/local/python3.11.10/lib/python3.11/site-packages/torch_npu/npu/_backends.py", line 97, in get_soc_version
[1;36m(EngineCore_0 pid=285866)[0;0m ERROR 09-05 15:50:32 [multiproc_executor.py:567]     torch_npu.npu._lazy_init()
[1;36m(EngineCore_0 pid=285866)[0;0m ERROR 09-05 15:50:32 [multiproc_executor.py:567]   File "/usr/local/python3.11.10/lib/python3.11/site-packages/torch_npu/npu/__init__.py", line 242, in _lazy_init
[1;36m(EngineCore_0 pid=285866)[0;0m ERROR 09-05 15:50:32 [multiproc_executor.py:567]     torch_npu._C._npu_init()
[1;36m(EngineCore_0 pid=285866)[0;0m ERROR 09-05 15:50:32 [multiproc_executor.py:567] RuntimeError: SetPrecisionMode:build/CMakeFiles/torch_npu.dir/compiler_depend.ts:155 NPU function error: at_npu::native::AclSetCompileopt(aclCompileOpt::ACL_PRECISION_MODE, precision_mode), error code is 500001
[1;36m(EngineCore_0 pid=285866)[0;0m ERROR 09-05 15:50:32 [multiproc_executor.py:567] [ERROR] 2025-09-05-15:50:32 (PID:285908, Device:0, RankID:-1) ERR00100 PTA call acl api failed
[1;36m(EngineCore_0 pid=285866)[0;0m ERROR 09-05 15:50:32 [multiproc_executor.py:567] [Error]: The internal ACL of the system is incorrect.
[1;36m(EngineCore_0 pid=285866)[0;0m ERROR 09-05 15:50:32 [multiproc_executor.py:567]         Rectify the fault based on the error information in the ascend log.
[1;36m(EngineCore_0 pid=285866)[0;0m ERROR 09-05 15:50:32 [multiproc_executor.py:567] E40024: [PID: 285908] 2025-09-05-15:50:32.415.974 Failed call Python Func/Method [init_multi_process_env], Reason[Traceback (most recent call last):
[1;36m(EngineCore_0 pid=285866)[0;0m ERROR 09-05 15:50:32 [multiproc_executor.py:567]   File "/usr/local/Ascend/ascend-toolkit/latest/python/site-packages/te_fusion/parallel_compilation.py", line 945, in init_multi_process_env
[1;36m(EngineCore_0 pid=285866)[0;0m ERROR 09-05 15:50:32 [multiproc_executor.py:567]     compiler.init()
[1;36m(EngineCore_0 pid=285866)[0;0m ERROR 09-05 15:50:32 [multiproc_executor.py:567]   File "/usr/local/Ascend/ascend-toolkit/latest/python/site-packages/te_fusion/parallel_compilation.py", line 497, in init
[1;36m(EngineCore_0 pid=285866)[0;0m ERROR 09-05 15:50:32 [multiproc_executor.py:567]     self._build_random_op()
[1;36m(EngineCore_0 pid=285866)[0;0m ERROR 09-05 15:50:32 [multiproc_executor.py:567]   File "/usr/local/Ascend/ascend-toolkit/latest/python/site-packages/te_fusion/parallel_compilation.py", line 598, in _build_random_op
[1;36m(EngineCore_0 pid=285866)[0;0m ERROR 09-05 15:50:32 [multiproc_executor.py:567]     importlib.import_module("te.platform.vector_random_buff")
[1;36m(EngineCore_0 pid=285866)[0;0m ERROR 09-05 15:50:32 [multiproc_executor.py:567]   File "/usr/local/python3.11.10/lib/python3.11/importlib/__init__.py", line 126, in import_module
[1;36m(EngineCore_0 pid=285866)[0;0m ERROR 09-05 15:50:32 [multiproc_executor.py:567]     return _bootstrap._gcd_import(name[level:], package, level)
[1;36m(EngineCore_0 pid=285866)[0;0m ERROR 09-05 15:50:32 [multiproc_executor.py:567]            ^^^^^^^^^^^^^^^^^^^^^^^^^^^^^^^^^^^^^^^^^^^^^^^^^^^^
[1;36m(EngineCore_0 pid=285866)[0;0m ERROR 09-05 15:50:32 [multiproc_executor.py:567]   File "<frozen importlib._bootstrap>", line 1204, in _gcd_import
[1;36m(EngineCore_0 pid=285866)[0;0m ERROR 09-05 15:50:32 [multiproc_executor.py:567]   File "<frozen importlib._bootstrap>", line 1176, in _find_and_load
[1;36m(EngineCore_0 pid=285866)[0;0m ERROR 09-05 15:50:32 [multiproc_executor.py:567]   File "<frozen importlib._bootstrap>", line 1147, in _find_and_load_unlocked
[1;36m(EngineCore_0 pid=285866)[0;0m ERROR 09-05 15:50:32 [multiproc_executor.py:567]   File "<frozen importlib._bootstrap>", line 690, in _load_unlocked
[1;36m(EngineCore_0 pid=285866)[0;0m ERROR 09-05 15:50:32 [multiproc_executor.py:567]   File "<frozen importlib._bootstrap_external>", line 940, in exec_module
[1;36m(EngineCore_0 pid=285866)[0;0m ERROR 09-05 15:50:32 [multiproc_executor.py:567]   File "<frozen importlib._bootstrap>", line 241, in _call_with_frames_removed
[1;36m(EngineCore_0 pid=285866)[0;0m ERROR 09-05 15:50:32 [multiproc_executor.py:567]   File "/usr/local/Ascend/ascend-toolkit/latest/python/site-packages/te/platform/vector_random_buff.py", line 20, in <module>
[1;36m(EngineCore_0 pid=285866)[0;0m ERROR 09-05 15:50:32 [multiproc_executor.py:567]     from te import tik
[1;36m(EngineCore_0 pid=285866)[0;0m ERROR 09-05 15:50:32 [multiproc_executor.py:567]   File "/usr/local/Ascend/ascend-toolkit/latest/python/site-packages/te/tik/__init__.py", line 53, in <module>
[1;36m(EngineCore_0 pid=285866)[0;0m ERROR 09-05 15:50:32 [multiproc_executor.py:567]     from tbe.tik.api.tik_build import Tik
[1;36m(EngineCore_0 pid=285866)[0;0m ERROR 09-05 15:50:32 [multiproc_executor.py:567]   File "/usr/local/Ascend/ascend-toolkit/latest/python/site-packages/tbe/tik/__init__.py", line 53, in <module>
[1;36m(EngineCore_0 pid=285866)[0;0m ERROR 09-05 15:50:32 [multiproc_executor.py:567]     from tbe.tik.api.tik_build import Tik
[1;36m(EngineCore_0 pid=285866)[0;0m ERROR 09-05 15:50:32 [multiproc_executor.py:567]   File "/usr/local/Ascend/ascend-toolkit/latest/python/site-packages/tbe/tik/api/tik_build.py", line 39, in <module>
[1;36m(EngineCore_0 pid=285866)[0;0m ERROR 09-05 15:50:32 [multiproc_executor.py:567]     from tbe.tik.tik_lib import Expr
[1;36m(EngineCore_0 pid=285866)[0;0m ERROR 09-05 15:50:32 [multiproc_executor.py:567]   File "/usr/local/Ascend/ascend-toolkit/latest/python/site-packages/tbe/tik/tik_lib/__init__.py", line 13, in <module>
[1;36m(EngineCore_0 pid=285866)[0;0m ERROR 09-05 15:50:32 [multiproc_executor.py:567]     from tbe.tik.tik_lib.tik_vector_api_ import TikVectorApi
[1;36m(EngineCore_0 pid=285866)[0;0m ERROR 09-05 15:50:32 [multiproc_executor.py:567]   File "/usr/local/Ascend/ascend-toolkit/latest/python/site-packages/tbe/tik/tik_lib/tik_vector_api_.py", line 17, in <module>
[1;36m(EngineCore_0 pid=285866)[0;0m ERROR 09-05 15:50:32 [multiproc_executor.py:567]     from tbe.tik.api.tik_tensor import Tensor
[1;36m(EngineCore_0 pid=285866)[0;0m ERROR 09-05 15:50:32 [multiproc_executor.py:567]   File "/usr/local/Ascend/ascend-toolkit/latest/python/site-packages/tbe/tik/api/tik_tensor.py", line 26, in <module>
[1;36m(EngineCore_0 pid=285866)[0;0m ERROR 09-05 15:50:32 [multiproc_executor.py:567]     from tbe.tik.api.tik_scalar import Scalar
[1;36m(EngineCore_0 pid=285866)[0;0m ERROR 09-05 15:50:32 [multiproc_executor.py:567]   File "/usr/local/Ascend/ascend-toolkit/latest/python/site-packages/tbe/tik/api/tik_scalar.py", line 20, in <module>
[1;36m(EngineCore_0 pid=285866)[0;0m ERROR 09-05 15:50:32 [multiproc_executor.py:567]     from tbe.tik.debug.decorators import scalar_register
[1;36m(EngineCore_0 pid=285866)[0;0m ERROR 09-05 15:50:32 [multiproc_executor.py:567]   File "/usr/local/Ascend/ascend-toolkit/latest/python/site-packages/tbe/tik/debug/__init__.py", line 51, in <module>
[1;36m(EngineCore_0 pid=285866)[0;0m ERROR 09-05 15:50:32 [multiproc_executor.py:567]     from tbe.tik.debug.tik_vector_ops_debug.tik_vector_debug import vec_single_elewise_func_dec_new
[1;36m(EngineCore_0 pid=285866)[0;0m ERROR 09-05 15:50:32 [multiproc_executor.py:567]   File "/usr/local/Ascend/ascend-toolkit/latest/python/site-packages/tbe/tik/debug/tik_vector_ops_debug/tik_vector_debug.py", line 22, in <module>
[1;36m(EngineCore_0 pid=285866)[0;0m ERROR 09-05 15:50:32 [multiproc_executor.py:567]     from tbe.tik.debug.tik_vector_ops_debug.tik_vector_compare_debug_ import NewVcmp
[1;36m(EngineCore_0 pid=285866)[0;0m ERROR 09-05 15:50:32 [multiproc_executor.py:567]   File "<frozen importlib._bootstrap>", line 1176, in _find_and_load
[1;36m(EngineCore_0 pid=285866)[0;0m ERROR 09-05 15:50:32 [multiproc_executor.py:567]   File "<frozen importlib._bootstrap>", line 1147, in _find_and_load_unlocked
[1;36m(EngineCore_0 pid=285866)[0;0m ERROR 09-05 15:50:32 [multiproc_executor.py:567]   File "<frozen importlib._bootstrap>", line 690, in _load_unlocked
[1;36m(EngineCore_0 pid=285866)[0;0m ERROR 09-05 15:50:32 [multiproc_executor.py:567]   File "<frozen importlib._bootstrap_external>", line 936, in exec_module
[1;36m(EngineCore_0 pid=285866)[0;0m ERROR 09-05 15:50:32 [multiproc_executor.py:567]   File "<frozen importlib._bootstrap_external>", line 1069, in get_code
[1;36m(EngineCore_0 pid=285866)[0;0m ERROR 09-05 15:50:32 [multiproc_executor.py:567]   File "<frozen importlib._bootstrap_external>", line 729, in _compile_bytecode
[1;36m(EngineCore_0 pid=285866)[0;0m ERROR 09-05 15:50:32 [multiproc_executor.py:567]   File "/home/vllm/vllm/v1/executor/multiproc_executor.py", line 508, in signal_handler
[1;36m(EngineCore_0 pid=285866)[0;0m ERROR 09-05 15:50:32 [multiproc_executor.py:567]     raise SystemExit()
[1;36m(EngineCore_0 pid=285866)[0;0m ERROR 09-05 15:50:32 [multiproc_executor.py:567] SystemExit
[1;36m(EngineCore_0 pid=285866)[0;0m ERROR 09-05 15:50:32 [multiproc_executor.py:567] ] 
[1;36m(EngineCore_0 pid=285866)[0;0m ERROR 09-05 15:50:32 [multiproc_executor.py:567]         Possible Cause: The Python Func/Method does not exist.
[1;36m(EngineCore_0 pid=285866)[0;0m ERROR 09-05 15:50:32 [multiproc_executor.py:567]         Solution: 1.Check that the spelling of the invoked function is correct or the Python dependency library is installed.
[1;36m(EngineCore_0 pid=285866)[0;0m ERROR 09-05 15:50:32 [multiproc_executor.py:567] 2.Set CANN environment variables.
[1;36m(EngineCore_0 pid=285866)[0;0m ERROR 09-05 15:50:32 [multiproc_executor.py:567] 3.Reinstall the CANN package.
[1;36m(EngineCore_0 pid=285866)[0;0m ERROR 09-05 15:50:32 [multiproc_executor.py:567]         TraceBack (most recent call last):
[1;36m(EngineCore_0 pid=285866)[0;0m ERROR 09-05 15:50:32 [multiproc_executor.py:567]         Failed to call function init_multi_process_env[FUNC:InitParallelCompilation][FILE:python_adapter_manager.cc][LINE:180]
[1;36m(EngineCore_0 pid=285866)[0;0m ERROR 09-05 15:50:32 [multiproc_executor.py:567]         Failed to initialize TeConfigInfo.
[1;36m(EngineCore_0 pid=285866)[0;0m ERROR 09-05 15:50:32 [multiproc_executor.py:567]         [GraphOpt][InitializeInner][InitTbeFunc] Failed to init tbe.[FUNC:InitializeTeFusion][FILE:tbe_op_store_adapter.cc][LINE:1921]
[1;36m(EngineCore_0 pid=285866)[0;0m ERROR 09-05 15:50:32 [multiproc_executor.py:567]         [GraphOpt][InitializeInner][InitTeFusion]: Failed to initialize TeFusion.[FUNC:InitializeInner][FILE:tbe_op_store_adapter.cc][LINE:1888]
[1;36m(EngineCore_0 pid=285866)[0;0m ERROR 09-05 15:50:32 [multiproc_executor.py:567]         [SubGraphOpt][PreCompileOp][InitAdapter] InitializeAdapter adapter [tbe_op_adapter] failed! Ret [4294967295][FUNC:InitializeAdapter][FILE:op_store_adapter_manager.cc][LINE:79]
[1;36m(EngineCore_0 pid=285866)[0;0m ERROR 09-05 15:50:32 [multiproc_executor.py:567]         [SubGraphOpt][PreCompileOp][Init] Initialize op store adapter failed, OpsStoreName[tbe-custom].[FUNC:Initialize][FILE:op_store_adapter_manager.cc][LINE:120]
[1;36m(EngineCore_0 pid=285866)[0;0m ERROR 09-05 15:50:32 [multiproc_executor.py:567]         [FusionMngr][Init] Op store adapter manager init failed.[FUNC:Initialize][FILE:fusion_manager.cc][LINE:115]
[1;36m(EngineCore_0 pid=285866)[0;0m ERROR 09-05 15:50:32 [multiproc_executor.py:567]         PluginManager InvokeAll failed.[FUNC:Initialize][FILE:ops_kernel_manager.cc][LINE:83]
[1;36m(EngineCore_0 pid=285866)[0;0m ERROR 09-05 15:50:32 [multiproc_executor.py:567]         OpsManager initialize failed.[FUNC:InnerInitialize][FILE:gelib.cc][LINE:239]
[1;36m(EngineCore_0 pid=285866)[0;0m ERROR 09-05 15:50:32 [multiproc_executor.py:567]         GELib::InnerInitialize failed.[FUNC:Initialize][FILE:gelib.cc][LINE:164]
[1;36m(EngineCore_0 pid=285866)[0;0m ERROR 09-05 15:50:32 [multiproc_executor.py:567]         GEInitialize failed.[FUNC:GEInitialize][FILE:ge_api.cc][LINE:382]
[1;36m(EngineCore_0 pid=285866)[0;0m ERROR 09-05 15:50:32 [multiproc_executor.py:567]         [Initialize][Ge]GEInitialize failed. ge result = 4294967295[FUNC:ReportCallError][FILE:log_inner.cpp][LINE:161]
[1;36m(EngineCore_0 pid=285866)[0;0m ERROR 09-05 15:50:32 [multiproc_executor.py:567]         [Init][Compiler]Init compiler failed[FUNC:ReportInnerError][FILE:log_inner.cpp][LINE:145]
[1;36m(EngineCore_0 pid=285866)[0;0m ERROR 09-05 15:50:32 [multiproc_executor.py:567]         [Set][Options]OpCompileProcessor init failed![FUNC:ReportInnerError][FILE:log_inner.cpp][LINE:145]
[1;36m(EngineCore_0 pid=285866)[0;0m ERROR 09-05 15:50:32 [multiproc_executor.py:567] 
[1;36m(EngineCore_0 pid=285866)[0;0m ERROR 09-05 15:50:32 [multiproc_executor.py:567] WorkerProc failed to start.
[1;36m(EngineCore_0 pid=285866)[0;0m ERROR 09-05 15:50:32 [multiproc_executor.py:567] Traceback (most recent call last):
[1;36m(EngineCore_0 pid=285866)[0;0m ERROR 09-05 15:50:32 [multiproc_executor.py:567]   File "/home/vllm/vllm/v1/executor/multiproc_executor.py", line 541, in worker_main
[1;36m(EngineCore_0 pid=285866)[0;0m ERROR 09-05 15:50:32 [multiproc_executor.py:567]     worker = WorkerProc(*args, **kwargs)
[1;36m(EngineCore_0 pid=285866)[0;0m ERROR 09-05 15:50:32 [multiproc_executor.py:567]              ^^^^^^^^^^^^^^^^^^^^^^^^^^^
[1;36m(EngineCore_0 pid=285866)[0;0m ERROR 09-05 15:50:32 [multiproc_executor.py:567]   File "/home/vllm/vllm/v1/executor/multiproc_executor.py", line 387, in __init__
[1;36m(EngineCore_0 pid=285866)[0;0m ERROR 09-05 15:50:32 [multiproc_executor.py:567]     wrapper.init_worker(all_kwargs)
[1;36m(EngineCore_0 pid=285866)[0;0m ERROR 09-05 15:50:32 [multiproc_executor.py:567]   File "/home/vllm/vllm/worker/worker_base.py", line 592, in init_worker
[1;36m(EngineCore_0 pid=285866)[0;0m ERROR 09-05 15:50:32 [multiproc_executor.py:567]     self.worker = worker_class(**kwargs)
[1;36m(EngineCore_0 pid=285866)[0;0m ERROR 09-05 15:50:32 [multiproc_executor.py:567]                   ^^^^^^^^^^^^^^^^^^^^^^
[1;36m(EngineCore_0 pid=285866)[0;0m ERROR 09-05 15:50:32 [multiproc_executor.py:567]   File "/home/vllm-ascend-origin/vllm_ascend/worker/worker_v1.py", line 76, in __init__
[1;36m(EngineCore_0 pid=285866)[0;0m ERROR 09-05 15:50:32 [multiproc_executor.py:567]     init_ascend_soc_version()
[1;36m(EngineCore_0 pid=285866)[0;0m ERROR 09-05 15:50:32 [multiproc_executor.py:567]   File "/home/vllm-ascend-origin/vllm_ascend/utils.py", line 512, in init_ascend_soc_version
[1;36m(EngineCore_0 pid=285866)[0;0m ERROR 09-05 15:50:32 [multiproc_executor.py:567]     soc_version = torch_npu.npu.get_soc_version()
[1;36m(EngineCore_0 pid=285866)[0;0m ERROR 09-05 15:50:32 [multiproc_executor.py:567]                   ^^^^^^^^^^^^^^^^^^^^^^^^^^^^^^^
[1;36m(EngineCore_0 pid=285866)[0;0m ERROR 09-05 15:50:32 [multiproc_executor.py:567]   File "/usr/local/python3.11.10/lib/python3.11/site-packages/torch_npu/npu/_backends.py", line 97, in get_soc_version
[1;36m(EngineCore_0 pid=285866)[0;0m ERROR 09-05 15:50:32 [multiproc_executor.py:567]     torch_npu.npu._lazy_init()
[1;36m(EngineCore_0 pid=285866)[0;0m ERROR 09-05 15:50:32 [multiproc_executor.py:567]   File "/usr/local/python3.11.10/lib/python3.11/site-packages/torch_npu/npu/__init__.py", line 242, in _lazy_init
[1;36m(EngineCore_0 pid=285866)[0;0m ERROR 09-05 15:50:32 [multiproc_executor.py:567]     torch_npu._C._npu_init()
[1;36m(EngineCore_0 pid=285866)[0;0m ERROR 09-05 15:50:32 [multiproc_executor.py:567] RuntimeError: SetPrecisionMode:build/CMakeFiles/torch_npu.dir/compiler_depend.ts:155 NPU function error: at_npu::native::AclSetCompileopt(aclCompileOpt::ACL_PRECISION_MODE, precision_mode), error code is 500001
[1;36m(EngineCore_0 pid=285866)[0;0m ERROR 09-05 15:50:32 [multiproc_executor.py:567] [ERROR] 2025-09-05-15:50:32 (PID:285903, Device:0, RankID:-1) ERR00100 PTA call acl api failed
[1;36m(EngineCore_0 pid=285866)[0;0m ERROR 09-05 15:50:32 [multiproc_executor.py:567] [Error]: The internal ACL of the system is incorrect.
[1;36m(EngineCore_0 pid=285866)[0;0m ERROR 09-05 15:50:32 [multiproc_executor.py:567]         Rectify the fault based on the error information in the ascend log.
[1;36m(EngineCore_0 pid=285866)[0;0m ERROR 09-05 15:50:32 [multiproc_executor.py:567] E40024: [PID: 285903] 2025-09-05-15:50:32.500.890 Failed call Python Func/Method [init_multi_process_env], Reason[Traceback (most recent call last):
[1;36m(EngineCore_0 pid=285866)[0;0m ERROR 09-05 15:50:32 [multiproc_executor.py:567]   File "/usr/local/Ascend/ascend-toolkit/latest/python/site-packages/te_fusion/parallel_compilation.py", line 945, in init_multi_process_env
[1;36m(EngineCore_0 pid=285866)[0;0m ERROR 09-05 15:50:32 [multiproc_executor.py:567]     compiler.init()
[1;36m(EngineCore_0 pid=285866)[0;0m ERROR 09-05 15:50:32 [multiproc_executor.py:567]   File "/usr/local/Ascend/ascend-toolkit/latest/python/site-packages/te_fusion/parallel_compilation.py", line 497, in init
[1;36m(EngineCore_0 pid=285866)[0;0m ERROR 09-05 15:50:32 [multiproc_executor.py:567]     self._build_random_op()
[1;36m(EngineCore_0 pid=285866)[0;0m ERROR 09-05 15:50:32 [multiproc_executor.py:567]   File "/usr/local/Ascend/ascend-toolkit/latest/python/site-packages/te_fusion/parallel_compilation.py", line 598, in _build_random_op
[1;36m(EngineCore_0 pid=285866)[0;0m ERROR 09-05 15:50:32 [multiproc_executor.py:567]     importlib.import_module("te.platform.vector_random_buff")
[1;36m(EngineCore_0 pid=285866)[0;0m ERROR 09-05 15:50:32 [multiproc_executor.py:567]   File "/usr/local/python3.11.10/lib/python3.11/importlib/__init__.py", line 126, in import_module
[1;36m(EngineCore_0 pid=285866)[0;0m ERROR 09-05 15:50:32 [multiproc_executor.py:567]     return _bootstrap._gcd_import(name[level:], package, level)
[1;36m(EngineCore_0 pid=285866)[0;0m ERROR 09-05 15:50:32 [multiproc_executor.py:567]            ^^^^^^^^^^^^^^^^^^^^^^^^^^^^^^^^^^^^^^^^^^^^^^^^^^^^
[1;36m(EngineCore_0 pid=285866)[0;0m ERROR 09-05 15:50:32 [multiproc_executor.py:567]   File "<frozen importlib._bootstrap>", line 1204, in _gcd_import
[1;36m(EngineCore_0 pid=285866)[0;0m ERROR 09-05 15:50:32 [multiproc_executor.py:567]   File "<frozen importlib._bootstrap>", line 1176, in _find_and_load
[1;36m(EngineCore_0 pid=285866)[0;0m ERROR 09-05 15:50:32 [multiproc_executor.py:567]   File "<frozen importlib._bootstrap>", line 1147, in _find_and_load_unlocked
[1;36m(EngineCore_0 pid=285866)[0;0m ERROR 09-05 15:50:32 [multiproc_executor.py:567]   File "<frozen importlib._bootstrap>", line 690, in _load_unlocked
[1;36m(EngineCore_0 pid=285866)[0;0m ERROR 09-05 15:50:32 [multiproc_executor.py:567]   File "<frozen importlib._bootstrap_external>", line 940, in exec_module
[1;36m(EngineCore_0 pid=285866)[0;0m ERROR 09-05 15:50:32 [multiproc_executor.py:567]   File "<frozen importlib._bootstrap>", line 241, in _call_with_frames_removed
[1;36m(EngineCore_0 pid=285866)[0;0m ERROR 09-05 15:50:32 [multiproc_executor.py:567]   File "/usr/local/Ascend/ascend-toolkit/latest/python/site-packages/te/platform/vector_random_buff.py", line 20, in <module>
[1;36m(EngineCore_0 pid=285866)[0;0m ERROR 09-05 15:50:32 [multiproc_executor.py:567]     from te import tik
[1;36m(EngineCore_0 pid=285866)[0;0m ERROR 09-05 15:50:32 [multiproc_executor.py:567]   File "/usr/local/Ascend/ascend-toolkit/latest/python/site-packages/te/tik/__init__.py", line 53, in <module>
[1;36m(EngineCore_0 pid=285866)[0;0m ERROR 09-05 15:50:32 [multiproc_executor.py:567]     from tbe.tik.api.tik_build import Tik
[1;36m(EngineCore_0 pid=285866)[0;0m ERROR 09-05 15:50:32 [multiproc_executor.py:567]   File "/usr/local/Ascend/ascend-toolkit/latest/python/site-packages/tbe/tik/__init__.py", line 53, in <module>
[1;36m(EngineCore_0 pid=285866)[0;0m ERROR 09-05 15:50:32 [multiproc_executor.py:567]     from tbe.tik.api.tik_build import Tik
[1;36m(EngineCore_0 pid=285866)[0;0m ERROR 09-05 15:50:32 [multiproc_executor.py:567]   File "/usr/local/Ascend/ascend-toolkit/latest/python/site-packages/tbe/tik/api/tik_build.py", line 39, in <module>
[1;36m(EngineCore_0 pid=285866)[0;0m ERROR 09-05 15:50:32 [multiproc_executor.py:567]     from tbe.tik.tik_lib import Expr
[1;36m(EngineCore_0 pid=285866)[0;0m ERROR 09-05 15:50:32 [multiproc_executor.py:567]   File "/usr/local/Ascend/ascend-toolkit/latest/python/site-packages/tbe/tik/tik_lib/__init__.py", line 13, in <module>
[1;36m(EngineCore_0 pid=285866)[0;0m ERROR 09-05 15:50:32 [multiproc_executor.py:567]     from tbe.tik.tik_lib.tik_vector_api_ import TikVectorApi
[1;36m(EngineCore_0 pid=285866)[0;0m ERROR 09-05 15:50:32 [multiproc_executor.py:567]   File "/usr/local/Ascend/ascend-toolkit/latest/python/site-packages/tbe/tik/tik_lib/tik_vector_api_.py", line 17, in <module>
[1;36m(EngineCore_0 pid=285866)[0;0m ERROR 09-05 15:50:32 [multiproc_executor.py:567]     from tbe.tik.api.tik_tensor import Tensor
[1;36m(EngineCore_0 pid=285866)[0;0m ERROR 09-05 15:50:32 [multiproc_executor.py:567]   File "/usr/local/Ascend/ascend-toolkit/latest/python/site-packages/tbe/tik/api/tik_tensor.py", line 26, in <module>
[1;36m(EngineCore_0 pid=285866)[0;0m ERROR 09-05 15:50:32 [multiproc_executor.py:567]     from tbe.tik.api.tik_scalar import Scalar
[1;36m(EngineCore_0 pid=285866)[0;0m ERROR 09-05 15:50:32 [multiproc_executor.py:567]   File "/usr/local/Ascend/ascend-toolkit/latest/python/site-packages/tbe/tik/api/tik_scalar.py", line 20, in <module>
[1;36m(EngineCore_0 pid=285866)[0;0m ERROR 09-05 15:50:32 [multiproc_executor.py:567]     from tbe.tik.debug.decorators import scalar_register
[1;36m(EngineCore_0 pid=285866)[0;0m ERROR 09-05 15:50:32 [multiproc_executor.py:567]   File "/usr/local/Ascend/ascend-toolkit/latest/python/site-packages/tbe/tik/debug/__init__.py", line 51, in <module>
[1;36m(EngineCore_0 pid=285866)[0;0m ERROR 09-05 15:50:32 [multiproc_executor.py:567]     from tbe.tik.debug.tik_vector_ops_debug.tik_vector_debug import vec_single_elewise_func_dec_new
[1;36m(EngineCore_0 pid=285866)[0;0m ERROR 09-05 15:50:32 [multiproc_executor.py:567]   File "/usr/local/Ascend/ascend-toolkit/latest/python/site-packages/tbe/tik/debug/tik_vector_ops_debug/tik_vector_debug.py", line 22, in <module>
[1;36m(EngineCore_0 pid=285866)[0;0m ERROR 09-05 15:50:32 [multiproc_executor.py:567]     from tbe.tik.debug.tik_vector_ops_debug.tik_vector_compare_debug_ import NewVcmp
[1;36m(EngineCore_0 pid=285866)[0;0m ERROR 09-05 15:50:32 [multiproc_executor.py:567]   File "<frozen importlib._bootstrap>", line 1176, in _find_and_load
[1;36m(EngineCore_0 pid=285866)[0;0m ERROR 09-05 15:50:32 [multiproc_executor.py:567]   File "<frozen importlib._bootstrap>", line 1147, in _find_and_load_unlocked
[1;36m(EngineCore_0 pid=285866)[0;0m ERROR 09-05 15:50:32 [multiproc_executor.py:567]   File "<frozen importlib._bootstrap>", line 690, in _load_unlocked
[1;36m(EngineCore_0 pid=285866)[0;0m ERROR 09-05 15:50:32 [multiproc_executor.py:567]   File "<frozen importlib._bootstrap_external>", line 936, in exec_module
[1;36m(EngineCore_0 pid=285866)[0;0m ERROR 09-05 15:50:32 [multiproc_executor.py:567]   File "<frozen importlib._bootstrap_external>", line 1069, in get_code
[1;36m(EngineCore_0 pid=285866)[0;0m ERROR 09-05 15:50:32 [multiproc_executor.py:567]   File "<frozen importlib._bootstrap_external>", line 729, in _compile_bytecode
[1;36m(EngineCore_0 pid=285866)[0;0m ERROR 09-05 15:50:32 [multiproc_executor.py:567]   File "/home/vllm/vllm/v1/executor/multiproc_executor.py", line 508, in signal_handler
[1;36m(EngineCore_0 pid=285866)[0;0m ERROR 09-05 15:50:32 [multiproc_executor.py:567]     raise SystemExit()
[1;36m(EngineCore_0 pid=285866)[0;0m ERROR 09-05 15:50:32 [multiproc_executor.py:567] SystemExit
[1;36m(EngineCore_0 pid=285866)[0;0m ERROR 09-05 15:50:32 [multiproc_executor.py:567] ] 
[1;36m(EngineCore_0 pid=285866)[0;0m ERROR 09-05 15:50:32 [multiproc_executor.py:567]         Possible Cause: The Python Func/Method does not exist.
[1;36m(EngineCore_0 pid=285866)[0;0m ERROR 09-05 15:50:32 [multiproc_executor.py:567]         Solution: 1.Check that the spelling of the invoked function is correct or the Python dependency library is installed.
[1;36m(EngineCore_0 pid=285866)[0;0m ERROR 09-05 15:50:32 [multiproc_executor.py:567] 2.Set CANN environment variables.
[1;36m(EngineCore_0 pid=285866)[0;0m ERROR 09-05 15:50:32 [multiproc_executor.py:567] 3.Reinstall the CANN package.
[1;36m(EngineCore_0 pid=285866)[0;0m ERROR 09-05 15:50:32 [multiproc_executor.py:567]         TraceBack (most recent call last):
[1;36m(EngineCore_0 pid=285866)[0;0m ERROR 09-05 15:50:32 [multiproc_executor.py:567]         Failed to call function init_multi_process_env[FUNC:InitParallelCompilation][FILE:python_adapter_manager.cc][LINE:180]
[1;36m(EngineCore_0 pid=285866)[0;0m ERROR 09-05 15:50:32 [multiproc_executor.py:567]         Failed to initialize TeConfigInfo.
[1;36m(EngineCore_0 pid=285866)[0;0m ERROR 09-05 15:50:32 [multiproc_executor.py:567]         [GraphOpt][InitializeInner][InitTbeFunc] Failed to init tbe.[FUNC:InitializeTeFusion][FILE:tbe_op_store_adapter.cc][LINE:1921]
[1;36m(EngineCore_0 pid=285866)[0;0m ERROR 09-05 15:50:32 [multiproc_executor.py:567]         [GraphOpt][InitializeInner][InitTeFusion]: Failed to initialize TeFusion.[FUNC:InitializeInner][FILE:tbe_op_store_adapter.cc][LINE:1888]
[1;36m(EngineCore_0 pid=285866)[0;0m ERROR 09-05 15:50:32 [multiproc_executor.py:567]         [SubGraphOpt][PreCompileOp][InitAdapter] InitializeAdapter adapter [tbe_op_adapter] failed! Ret [4294967295][FUNC:InitializeAdapter][FILE:op_store_adapter_manager.cc][LINE:79]
[1;36m(EngineCore_0 pid=285866)[0;0m ERROR 09-05 15:50:32 [multiproc_executor.py:567]         [SubGraphOpt][PreCompileOp][Init] Initialize op store adapter failed, OpsStoreName[tbe-custom].[FUNC:Initialize][FILE:op_store_adapter_manager.cc][LINE:120]
[1;36m(EngineCore_0 pid=285866)[0;0m ERROR 09-05 15:50:32 [multiproc_executor.py:567]         [FusionMngr][Init] Op store adapter manager init failed.[FUNC:Initialize][FILE:fusion_manager.cc][LINE:115]
[1;36m(EngineCore_0 pid=285866)[0;0m ERROR 09-05 15:50:32 [multiproc_executor.py:567]         PluginManager InvokeAll failed.[FUNC:Initialize][FILE:ops_kernel_manager.cc][LINE:83]
[1;36m(EngineCore_0 pid=285866)[0;0m ERROR 09-05 15:50:32 [multiproc_executor.py:567]         OpsManager initialize failed.[FUNC:InnerInitialize][FILE:gelib.cc][LINE:239]
[1;36m(EngineCore_0 pid=285866)[0;0m ERROR 09-05 15:50:32 [multiproc_executor.py:567]         GELib::InnerInitialize failed.[FUNC:Initialize][FILE:gelib.cc][LINE:164]
[1;36m(EngineCore_0 pid=285866)[0;0m ERROR 09-05 15:50:32 [multiproc_executor.py:567]         GEInitialize failed.[FUNC:GEInitialize][FILE:ge_api.cc][LINE:382]
[1;36m(EngineCore_0 pid=285866)[0;0m ERROR 09-05 15:50:32 [multiproc_executor.py:567]         [Initialize][Ge]GEInitialize failed. ge result = 4294967295[FUNC:ReportCallError][FILE:log_inner.cpp][LINE:161]
[1;36m(EngineCore_0 pid=285866)[0;0m ERROR 09-05 15:50:32 [multiproc_executor.py:567]         [Init][Compiler]Init compiler failed[FUNC:ReportInnerError][FILE:log_inner.cpp][LINE:145]
[1;36m(EngineCore_0 pid=285866)[0;0m ERROR 09-05 15:50:32 [multiproc_executor.py:567]         [Set][Options]OpCompileProcessor init failed![FUNC:ReportInnerError][FILE:log_inner.cpp][LINE:145]
[1;36m(EngineCore_0 pid=285866)[0;0m ERROR 09-05 15:50:32 [multiproc_executor.py:567] 
[1;36m(EngineCore_0 pid=285866)[0;0m ERROR 09-05 15:50:32 [multiproc_executor.py:567] WorkerProc failed to start.
[1;36m(EngineCore_0 pid=285866)[0;0m ERROR 09-05 15:50:32 [multiproc_executor.py:567] Traceback (most recent call last):
[1;36m(EngineCore_0 pid=285866)[0;0m ERROR 09-05 15:50:32 [multiproc_executor.py:567]   File "/home/vllm/vllm/v1/executor/multiproc_executor.py", line 541, in worker_main
[1;36m(EngineCore_0 pid=285866)[0;0m ERROR 09-05 15:50:32 [multiproc_executor.py:567]     worker = WorkerProc(*args, **kwargs)
[1;36m(EngineCore_0 pid=285866)[0;0m ERROR 09-05 15:50:32 [multiproc_executor.py:567]              ^^^^^^^^^^^^^^^^^^^^^^^^^^^
[1;36m(EngineCore_0 pid=285866)[0;0m ERROR 09-05 15:50:32 [multiproc_executor.py:567]   File "/home/vllm/vllm/v1/executor/multiproc_executor.py", line 387, in __init__
[1;36m(EngineCore_0 pid=285866)[0;0m ERROR 09-05 15:50:32 [multiproc_executor.py:567]     wrapper.init_worker(all_kwargs)
[1;36m(EngineCore_0 pid=285866)[0;0m ERROR 09-05 15:50:32 [multiproc_executor.py:567]   File "/home/vllm/vllm/worker/worker_base.py", line 592, in init_worker
[1;36m(EngineCore_0 pid=285866)[0;0m ERROR 09-05 15:50:32 [multiproc_executor.py:567]     self.worker = worker_class(**kwargs)
[1;36m(EngineCore_0 pid=285866)[0;0m ERROR 09-05 15:50:32 [multiproc_executor.py:567]                   ^^^^^^^^^^^^^^^^^^^^^^
[1;36m(EngineCore_0 pid=285866)[0;0m ERROR 09-05 15:50:32 [multiproc_executor.py:567]   File "/home/vllm-ascend-origin/vllm_ascend/worker/worker_v1.py", line 76, in __init__
[1;36m(EngineCore_0 pid=285866)[0;0m ERROR 09-05 15:50:32 [multiproc_executor.py:567]     init_ascend_soc_version()
[1;36m(EngineCore_0 pid=285866)[0;0m ERROR 09-05 15:50:32 [multiproc_executor.py:567]   File "/home/vllm-ascend-origin/vllm_ascend/utils.py", line 512, in init_ascend_soc_version
[1;36m(EngineCore_0 pid=285866)[0;0m ERROR 09-05 15:50:32 [multiproc_executor.py:567]     soc_version = torch_npu.npu.get_soc_version()
[1;36m(EngineCore_0 pid=285866)[0;0m ERROR 09-05 15:50:32 [multiproc_executor.py:567]                   ^^^^^^^^^^^^^^^^^^^^^^^^^^^^^^^
[1;36m(EngineCore_0 pid=285866)[0;0m ERROR 09-05 15:50:32 [multiproc_executor.py:567]   File "/usr/local/python3.11.10/lib/python3.11/site-packages/torch_npu/npu/_backends.py", line 97, in get_soc_version
[1;36m(EngineCore_0 pid=285866)[0;0m ERROR 09-05 15:50:32 [multiproc_executor.py:567]     torch_npu.npu._lazy_init()
[1;36m(EngineCore_0 pid=285866)[0;0m ERROR 09-05 15:50:32 [multiproc_executor.py:567]   File "/usr/local/python3.11.10/lib/python3.11/site-packages/torch_npu/npu/__init__.py", line 242, in _lazy_init
[1;36m(EngineCore_0 pid=285866)[0;0m ERROR 09-05 15:50:32 [multiproc_executor.py:567]     torch_npu._C._npu_init()
[1;36m(EngineCore_0 pid=285866)[0;0m ERROR 09-05 15:50:32 [multiproc_executor.py:567] RuntimeError: SetPrecisionMode:build/CMakeFiles/torch_npu.dir/compiler_depend.ts:155 NPU function error: at_npu::native::AclSetCompileopt(aclCompileOpt::ACL_PRECISION_MODE, precision_mode), error code is 500001
[1;36m(EngineCore_0 pid=285866)[0;0m ERROR 09-05 15:50:32 [multiproc_executor.py:567] [ERROR] 2025-09-05-15:50:32 (PID:285873, Device:0, RankID:-1) ERR00100 PTA call acl api failed
[1;36m(EngineCore_0 pid=285866)[0;0m ERROR 09-05 15:50:32 [multiproc_executor.py:567] [Error]: The internal ACL of the system is incorrect.
[1;36m(EngineCore_0 pid=285866)[0;0m ERROR 09-05 15:50:32 [multiproc_executor.py:567]         Rectify the fault based on the error information in the ascend log.
[1;36m(EngineCore_0 pid=285866)[0;0m ERROR 09-05 15:50:32 [multiproc_executor.py:567] E40024: [PID: 285873] 2025-09-05-15:50:32.520.661 Failed call Python Func/Method [init_multi_process_env], Reason[Traceback (most recent call last):
[1;36m(EngineCore_0 pid=285866)[0;0m ERROR 09-05 15:50:32 [multiproc_executor.py:567]   File "/usr/local/Ascend/ascend-toolkit/latest/python/site-packages/te_fusion/parallel_compilation.py", line 945, in init_multi_process_env
[1;36m(EngineCore_0 pid=285866)[0;0m ERROR 09-05 15:50:32 [multiproc_executor.py:567]     compiler.init()
[1;36m(EngineCore_0 pid=285866)[0;0m ERROR 09-05 15:50:32 [multiproc_executor.py:567]   File "/usr/local/Ascend/ascend-toolkit/latest/python/site-packages/te_fusion/parallel_compilation.py", line 497, in init
[1;36m(EngineCore_0 pid=285866)[0;0m ERROR 09-05 15:50:32 [multiproc_executor.py:567]     self._build_random_op()
[1;36m(EngineCore_0 pid=285866)[0;0m ERROR 09-05 15:50:32 [multiproc_executor.py:567]   File "/usr/local/Ascend/ascend-toolkit/latest/python/site-packages/te_fusion/parallel_compilation.py", line 598, in _build_random_op
[1;36m(EngineCore_0 pid=285866)[0;0m ERROR 09-05 15:50:32 [multiproc_executor.py:567]     importlib.import_module("te.platform.vector_random_buff")
[1;36m(EngineCore_0 pid=285866)[0;0m ERROR 09-05 15:50:32 [multiproc_executor.py:567]   File "/usr/local/python3.11.10/lib/python3.11/importlib/__init__.py", line 126, in import_module
[1;36m(EngineCore_0 pid=285866)[0;0m ERROR 09-05 15:50:32 [multiproc_executor.py:567]     return _bootstrap._gcd_import(name[level:], package, level)
[1;36m(EngineCore_0 pid=285866)[0;0m ERROR 09-05 15:50:32 [multiproc_executor.py:567]            ^^^^^^^^^^^^^^^^^^^^^^^^^^^^^^^^^^^^^^^^^^^^^^^^^^^^
[1;36m(EngineCore_0 pid=285866)[0;0m ERROR 09-05 15:50:32 [multiproc_executor.py:567]   File "<frozen importlib._bootstrap>", line 1204, in _gcd_import
[1;36m(EngineCore_0 pid=285866)[0;0m ERROR 09-05 15:50:32 [multiproc_executor.py:567]   File "<frozen importlib._bootstrap>", line 1176, in _find_and_load
[1;36m(EngineCore_0 pid=285866)[0;0m ERROR 09-05 15:50:32 [multiproc_executor.py:567]   File "<frozen importlib._bootstrap>", line 1147, in _find_and_load_unlocked
[1;36m(EngineCore_0 pid=285866)[0;0m ERROR 09-05 15:50:32 [multiproc_executor.py:567]   File "<frozen importlib._bootstrap>", line 690, in _load_unlocked
[1;36m(EngineCore_0 pid=285866)[0;0m ERROR 09-05 15:50:32 [multiproc_executor.py:567]   File "<frozen importlib._bootstrap_external>", line 940, in exec_module
[1;36m(EngineCore_0 pid=285866)[0;0m ERROR 09-05 15:50:32 [multiproc_executor.py:567]   File "<frozen importlib._bootstrap>", line 241, in _call_with_frames_removed
[1;36m(EngineCore_0 pid=285866)[0;0m ERROR 09-05 15:50:32 [multiproc_executor.py:567]   File "/usr/local/Ascend/ascend-toolkit/latest/python/site-packages/te/platform/vector_random_buff.py", line 20, in <module>
[1;36m(EngineCore_0 pid=285866)[0;0m ERROR 09-05 15:50:32 [multiproc_executor.py:567]     from te import tik
[1;36m(EngineCore_0 pid=285866)[0;0m ERROR 09-05 15:50:32 [multiproc_executor.py:567]   File "/usr/local/Ascend/ascend-toolkit/latest/python/site-packages/te/tik/__init__.py", line 53, in <module>
[1;36m(EngineCore_0 pid=285866)[0;0m ERROR 09-05 15:50:32 [multiproc_executor.py:567]     from tbe.tik.api.tik_build import Tik
[1;36m(EngineCore_0 pid=285866)[0;0m ERROR 09-05 15:50:32 [multiproc_executor.py:567]   File "/usr/local/Ascend/ascend-toolkit/latest/python/site-packages/tbe/tik/__init__.py", line 53, in <module>
[1;36m(EngineCore_0 pid=285866)[0;0m ERROR 09-05 15:50:32 [multiproc_executor.py:567]     from tbe.tik.api.tik_build import Tik
[1;36m(EngineCore_0 pid=285866)[0;0m ERROR 09-05 15:50:32 [multiproc_executor.py:567]   File "/usr/local/Ascend/ascend-toolkit/latest/python/site-packages/tbe/tik/api/tik_build.py", line 39, in <module>
[1;36m(EngineCore_0 pid=285866)[0;0m ERROR 09-05 15:50:32 [multiproc_executor.py:567]     from tbe.tik.tik_lib import Expr
[1;36m(EngineCore_0 pid=285866)[0;0m ERROR 09-05 15:50:32 [multiproc_executor.py:567]   File "/usr/local/Ascend/ascend-toolkit/latest/python/site-packages/tbe/tik/tik_lib/__init__.py", line 13, in <module>
[1;36m(EngineCore_0 pid=285866)[0;0m ERROR 09-05 15:50:32 [multiproc_executor.py:567]     from tbe.tik.tik_lib.tik_vector_api_ import TikVectorApi
[1;36m(EngineCore_0 pid=285866)[0;0m ERROR 09-05 15:50:32 [multiproc_executor.py:567]   File "/usr/local/Ascend/ascend-toolkit/latest/python/site-packages/tbe/tik/tik_lib/tik_vector_api_.py", line 17, in <module>
[1;36m(EngineCore_0 pid=285866)[0;0m ERROR 09-05 15:50:32 [multiproc_executor.py:567]     from tbe.tik.api.tik_tensor import Tensor
[1;36m(EngineCore_0 pid=285866)[0;0m ERROR 09-05 15:50:32 [multiproc_executor.py:567]   File "/usr/local/Ascend/ascend-toolkit/latest/python/site-packages/tbe/tik/api/tik_tensor.py", line 26, in <module>
[1;36m(EngineCore_0 pid=285866)[0;0m ERROR 09-05 15:50:32 [multiproc_executor.py:567]     from tbe.tik.api.tik_scalar import Scalar
[1;36m(EngineCore_0 pid=285866)[0;0m ERROR 09-05 15:50:32 [multiproc_executor.py:567]   File "/usr/local/Ascend/ascend-toolkit/latest/python/site-packages/tbe/tik/api/tik_scalar.py", line 20, in <module>
[1;36m(EngineCore_0 pid=285866)[0;0m ERROR 09-05 15:50:32 [multiproc_executor.py:567]     from tbe.tik.debug.decorators import scalar_register
[1;36m(EngineCore_0 pid=285866)[0;0m ERROR 09-05 15:50:32 [multiproc_executor.py:567]   File "/usr/local/Ascend/ascend-toolkit/latest/python/site-packages/tbe/tik/debug/__init__.py", line 51, in <module>
[1;36m(EngineCore_0 pid=285866)[0;0m ERROR 09-05 15:50:32 [multiproc_executor.py:567]     from tbe.tik.debug.tik_vector_ops_debug.tik_vector_debug import vec_single_elewise_func_dec_new
[1;36m(EngineCore_0 pid=285866)[0;0m ERROR 09-05 15:50:32 [multiproc_executor.py:567]   File "/usr/local/Ascend/ascend-toolkit/latest/python/site-packages/tbe/tik/debug/tik_vector_ops_debug/tik_vector_debug.py", line 22, in <module>
[1;36m(EngineCore_0 pid=285866)[0;0m ERROR 09-05 15:50:32 [multiproc_executor.py:567]     from tbe.tik.debug.tik_vector_ops_debug.tik_vector_compare_debug_ import NewVcmp
[1;36m(EngineCore_0 pid=285866)[0;0m ERROR 09-05 15:50:32 [multiproc_executor.py:567]   File "<frozen importlib._bootstrap>", line 1176, in _find_and_load
[1;36m(EngineCore_0 pid=285866)[0;0m ERROR 09-05 15:50:32 [multiproc_executor.py:567]   File "<frozen importlib._bootstrap>", line 1147, in _find_and_load_unlocked
[1;36m(EngineCore_0 pid=285866)[0;0m ERROR 09-05 15:50:32 [multiproc_executor.py:567]   File "<frozen importlib._bootstrap>", line 690, in _load_unlocked
[1;36m(EngineCore_0 pid=285866)[0;0m ERROR 09-05 15:50:32 [multiproc_executor.py:567]   File "<frozen importlib._bootstrap_external>", line 936, in exec_module
[1;36m(EngineCore_0 pid=285866)[0;0m ERROR 09-05 15:50:32 [multiproc_executor.py:567]   File "<frozen importlib._bootstrap_external>", line 1069, in get_code
[1;36m(EngineCore_0 pid=285866)[0;0m ERROR 09-05 15:50:32 [multiproc_executor.py:567]   File "<frozen importlib._bootstrap_external>", line 729, in _compile_bytecode
[1;36m(EngineCore_0 pid=285866)[0;0m ERROR 09-05 15:50:32 [multiproc_executor.py:567]   File "/home/vllm/vllm/v1/executor/multiproc_executor.py", line 508, in signal_handler
[1;36m(EngineCore_0 pid=285866)[0;0m ERROR 09-05 15:50:32 [multiproc_executor.py:567]     raise SystemExit()
[1;36m(EngineCore_0 pid=285866)[0;0m ERROR 09-05 15:50:32 [multiproc_executor.py:567] SystemExit
[1;36m(EngineCore_0 pid=285866)[0;0m ERROR 09-05 15:50:32 [multiproc_executor.py:567] ] 
[1;36m(EngineCore_0 pid=285866)[0;0m ERROR 09-05 15:50:32 [multiproc_executor.py:567]         Possible Cause: The Python Func/Method does not exist.
[1;36m(EngineCore_0 pid=285866)[0;0m ERROR 09-05 15:50:32 [multiproc_executor.py:567]         Solution: 1.Check that the spelling of the invoked function is correct or the Python dependency library is installed.
[1;36m(EngineCore_0 pid=285866)[0;0m ERROR 09-05 15:50:32 [multiproc_executor.py:567] 2.Set CANN environment variables.
[1;36m(EngineCore_0 pid=285866)[0;0m ERROR 09-05 15:50:32 [multiproc_executor.py:567] 3.Reinstall the CANN package.
[1;36m(EngineCore_0 pid=285866)[0;0m ERROR 09-05 15:50:32 [multiproc_executor.py:567]         TraceBack (most recent call last):
[1;36m(EngineCore_0 pid=285866)[0;0m ERROR 09-05 15:50:32 [multiproc_executor.py:567]         Failed to call function init_multi_process_env[FUNC:InitParallelCompilation][FILE:python_adapter_manager.cc][LINE:180]
[1;36m(EngineCore_0 pid=285866)[0;0m ERROR 09-05 15:50:32 [multiproc_executor.py:567]         Failed to initialize TeConfigInfo.
[1;36m(EngineCore_0 pid=285866)[0;0m ERROR 09-05 15:50:32 [multiproc_executor.py:567]         [GraphOpt][InitializeInner][InitTbeFunc] Failed to init tbe.[FUNC:InitializeTeFusion][FILE:tbe_op_store_adapter.cc][LINE:1921]
[1;36m(EngineCore_0 pid=285866)[0;0m ERROR 09-05 15:50:32 [multiproc_executor.py:567]         [GraphOpt][InitializeInner][InitTeFusion]: Failed to initialize TeFusion.[FUNC:InitializeInner][FILE:tbe_op_store_adapter.cc][LINE:1888]
[1;36m(EngineCore_0 pid=285866)[0;0m ERROR 09-05 15:50:32 [multiproc_executor.py:567]         [SubGraphOpt][PreCompileOp][InitAdapter] InitializeAdapter adapter [tbe_op_adapter] failed! Ret [4294967295][FUNC:InitializeAdapter][FILE:op_store_adapter_manager.cc][LINE:79]
[1;36m(EngineCore_0 pid=285866)[0;0m ERROR 09-05 15:50:32 [multiproc_executor.py:567]         [SubGraphOpt][PreCompileOp][Init] Initialize op store adapter failed, OpsStoreName[tbe-custom].[FUNC:Initialize][FILE:op_store_adapter_manager.cc][LINE:120]
[1;36m(EngineCore_0 pid=285866)[0;0m ERROR 09-05 15:50:32 [multiproc_executor.py:567]         [FusionMngr][Init] Op store adapter manager init failed.[FUNC:Initialize][FILE:fusion_manager.cc][LINE:115]
[1;36m(EngineCore_0 pid=285866)[0;0m ERROR 09-05 15:50:32 [multiproc_executor.py:567]         PluginManager InvokeAll failed.[FUNC:Initialize][FILE:ops_kernel_manager.cc][LINE:83]
[1;36m(EngineCore_0 pid=285866)[0;0m ERROR 09-05 15:50:32 [multiproc_executor.py:567]         OpsManager initialize failed.[FUNC:InnerInitialize][FILE:gelib.cc][LINE:239]
[1;36m(EngineCore_0 pid=285866)[0;0m ERROR 09-05 15:50:32 [multiproc_executor.py:567]         GELib::InnerInitialize failed.[FUNC:Initialize][FILE:gelib.cc][LINE:164]
[1;36m(EngineCore_0 pid=285866)[0;0m ERROR 09-05 15:50:32 [multiproc_executor.py:567]         GEInitialize failed.[FUNC:GEInitialize][FILE:ge_api.cc][LINE:382]
[1;36m(EngineCore_0 pid=285866)[0;0m ERROR 09-05 15:50:32 [multiproc_executor.py:567]         [Initialize][Ge]GEInitialize failed. ge result = 4294967295[FUNC:ReportCallError][FILE:log_inner.cpp][LINE:161]
[1;36m(EngineCore_0 pid=285866)[0;0m ERROR 09-05 15:50:32 [multiproc_executor.py:567]         [Init][Compiler]Init compiler failed[FUNC:ReportInnerError][FILE:log_inner.cpp][LINE:145]
[1;36m(EngineCore_0 pid=285866)[0;0m ERROR 09-05 15:50:32 [multiproc_executor.py:567]         [Set][Options]OpCompileProcessor init failed![FUNC:ReportInnerError][FILE:log_inner.cpp][LINE:145]
[1;36m(EngineCore_0 pid=285866)[0;0m ERROR 09-05 15:50:32 [multiproc_executor.py:567] 
[1;36m(EngineCore_0 pid=285866)[0;0m ERROR 09-05 15:50:32 [multiproc_executor.py:567] WorkerProc failed to start.
[1;36m(EngineCore_0 pid=285866)[0;0m ERROR 09-05 15:50:32 [multiproc_executor.py:567] Traceback (most recent call last):
[1;36m(EngineCore_0 pid=285866)[0;0m ERROR 09-05 15:50:32 [multiproc_executor.py:567]   File "/home/vllm/vllm/v1/executor/multiproc_executor.py", line 541, in worker_main
[1;36m(EngineCore_0 pid=285866)[0;0m ERROR 09-05 15:50:32 [multiproc_executor.py:567]     worker = WorkerProc(*args, **kwargs)
[1;36m(EngineCore_0 pid=285866)[0;0m ERROR 09-05 15:50:32 [multiproc_executor.py:567]              ^^^^^^^^^^^^^^^^^^^^^^^^^^^
[1;36m(EngineCore_0 pid=285866)[0;0m ERROR 09-05 15:50:32 [multiproc_executor.py:567]   File "/home/vllm/vllm/v1/executor/multiproc_executor.py", line 387, in __init__
[1;36m(EngineCore_0 pid=285866)[0;0m ERROR 09-05 15:50:32 [multiproc_executor.py:567]     wrapper.init_worker(all_kwargs)
[1;36m(EngineCore_0 pid=285866)[0;0m ERROR 09-05 15:50:32 [multiproc_executor.py:567]   File "/home/vllm/vllm/worker/worker_base.py", line 592, in init_worker
[1;36m(EngineCore_0 pid=285866)[0;0m ERROR 09-05 15:50:32 [multiproc_executor.py:567]     self.worker = worker_class(**kwargs)
[1;36m(EngineCore_0 pid=285866)[0;0m ERROR 09-05 15:50:32 [multiproc_executor.py:567]                   ^^^^^^^^^^^^^^^^^^^^^^
[1;36m(EngineCore_0 pid=285866)[0;0m ERROR 09-05 15:50:32 [multiproc_executor.py:567]   File "/home/vllm-ascend-origin/vllm_ascend/worker/worker_v1.py", line 76, in __init__
[1;36m(EngineCore_0 pid=285866)[0;0m ERROR 09-05 15:50:32 [multiproc_executor.py:567]     init_ascend_soc_version()
[1;36m(EngineCore_0 pid=285866)[0;0m ERROR 09-05 15:50:32 [multiproc_executor.py:567]   File "/home/vllm-ascend-origin/vllm_ascend/utils.py", line 512, in init_ascend_soc_version
[1;36m(EngineCore_0 pid=285866)[0;0m ERROR 09-05 15:50:32 [multiproc_executor.py:567]     soc_version = torch_npu.npu.get_soc_version()
[1;36m(EngineCore_0 pid=285866)[0;0m ERROR 09-05 15:50:32 [multiproc_executor.py:567]                   ^^^^^^^^^^^^^^^^^^^^^^^^^^^^^^^
[1;36m(EngineCore_0 pid=285866)[0;0m ERROR 09-05 15:50:32 [multiproc_executor.py:567]   File "/usr/local/python3.11.10/lib/python3.11/site-packages/torch_npu/npu/_backends.py", line 97, in get_soc_version
[1;36m(EngineCore_0 pid=285866)[0;0m ERROR 09-05 15:50:32 [multiproc_executor.py:567]     torch_npu.npu._lazy_init()
[1;36m(EngineCore_0 pid=285866)[0;0m ERROR 09-05 15:50:32 [multiproc_executor.py:567]   File "/usr/local/python3.11.10/lib/python3.11/site-packages/torch_npu/npu/__init__.py", line 242, in _lazy_init
[1;36m(EngineCore_0 pid=285866)[0;0m ERROR 09-05 15:50:32 [multiproc_executor.py:567]     torch_npu._C._npu_init()
[1;36m(EngineCore_0 pid=285866)[0;0m ERROR 09-05 15:50:32 [multiproc_executor.py:567] RuntimeError: SetPrecisionMode:build/CMakeFiles/torch_npu.dir/compiler_depend.ts:155 NPU function error: at_npu::native::AclSetCompileopt(aclCompileOpt::ACL_PRECISION_MODE, precision_mode), error code is 500001
[1;36m(EngineCore_0 pid=285866)[0;0m ERROR 09-05 15:50:32 [multiproc_executor.py:567] [ERROR] 2025-09-05-15:50:32 (PID:285888, Device:0, RankID:-1) ERR00100 PTA call acl api failed
[1;36m(EngineCore_0 pid=285866)[0;0m ERROR 09-05 15:50:32 [multiproc_executor.py:567] [Error]: The internal ACL of the system is incorrect.
[1;36m(EngineCore_0 pid=285866)[0;0m ERROR 09-05 15:50:32 [multiproc_executor.py:567]         Rectify the fault based on the error information in the ascend log.
[1;36m(EngineCore_0 pid=285866)[0;0m ERROR 09-05 15:50:32 [multiproc_executor.py:567] E40024: [PID: 285888] 2025-09-05-15:50:32.520.681 Failed call Python Func/Method [init_multi_process_env], Reason[Traceback (most recent call last):
[1;36m(EngineCore_0 pid=285866)[0;0m ERROR 09-05 15:50:32 [multiproc_executor.py:567]   File "/usr/local/Ascend/ascend-toolkit/latest/python/site-packages/te_fusion/parallel_compilation.py", line 945, in init_multi_process_env
[1;36m(EngineCore_0 pid=285866)[0;0m ERROR 09-05 15:50:32 [multiproc_executor.py:567]     compiler.init()
[1;36m(EngineCore_0 pid=285866)[0;0m ERROR 09-05 15:50:32 [multiproc_executor.py:567]   File "/usr/local/Ascend/ascend-toolkit/latest/python/site-packages/te_fusion/parallel_compilation.py", line 497, in init
[1;36m(EngineCore_0 pid=285866)[0;0m ERROR 09-05 15:50:32 [multiproc_executor.py:567]     self._build_random_op()
[1;36m(EngineCore_0 pid=285866)[0;0m ERROR 09-05 15:50:32 [multiproc_executor.py:567]   File "/usr/local/Ascend/ascend-toolkit/latest/python/site-packages/te_fusion/parallel_compilation.py", line 598, in _build_random_op
[1;36m(EngineCore_0 pid=285866)[0;0m ERROR 09-05 15:50:32 [multiproc_executor.py:567]     importlib.import_module("te.platform.vector_random_buff")
[1;36m(EngineCore_0 pid=285866)[0;0m ERROR 09-05 15:50:32 [multiproc_executor.py:567]   File "/usr/local/python3.11.10/lib/python3.11/importlib/__init__.py", line 126, in import_module
[1;36m(EngineCore_0 pid=285866)[0;0m ERROR 09-05 15:50:32 [multiproc_executor.py:567]     return _bootstrap._gcd_import(name[level:], package, level)
[1;36m(EngineCore_0 pid=285866)[0;0m ERROR 09-05 15:50:32 [multiproc_executor.py:567]            ^^^^^^^^^^^^^^^^^^^^^^^^^^^^^^^^^^^^^^^^^^^^^^^^^^^^
[1;36m(EngineCore_0 pid=285866)[0;0m ERROR 09-05 15:50:32 [multiproc_executor.py:567]   File "<frozen importlib._bootstrap>", line 1204, in _gcd_import
[1;36m(EngineCore_0 pid=285866)[0;0m ERROR 09-05 15:50:32 [multiproc_executor.py:567]   File "<frozen importlib._bootstrap>", line 1176, in _find_and_load
[1;36m(EngineCore_0 pid=285866)[0;0m ERROR 09-05 15:50:32 [multiproc_executor.py:567]   File "<frozen importlib._bootstrap>", line 1147, in _find_and_load_unlocked
[1;36m(EngineCore_0 pid=285866)[0;0m ERROR 09-05 15:50:32 [multiproc_executor.py:567]   File "<frozen importlib._bootstrap>", line 690, in _load_unlocked
[1;36m(EngineCore_0 pid=285866)[0;0m ERROR 09-05 15:50:32 [multiproc_executor.py:567]   File "<frozen importlib._bootstrap_external>", line 940, in exec_module
[1;36m(EngineCore_0 pid=285866)[0;0m ERROR 09-05 15:50:32 [multiproc_executor.py:567]   File "<frozen importlib._bootstrap>", line 241, in _call_with_frames_removed
[1;36m(EngineCore_0 pid=285866)[0;0m ERROR 09-05 15:50:32 [multiproc_executor.py:567]   File "/usr/local/Ascend/ascend-toolkit/latest/python/site-packages/te/platform/vector_random_buff.py", line 20, in <module>
[1;36m(EngineCore_0 pid=285866)[0;0m ERROR 09-05 15:50:32 [multiproc_executor.py:567]     from te import tik
[1;36m(EngineCore_0 pid=285866)[0;0m ERROR 09-05 15:50:32 [multiproc_executor.py:567]   File "/usr/local/Ascend/ascend-toolkit/latest/python/site-packages/te/tik/__init__.py", line 53, in <module>
[1;36m(EngineCore_0 pid=285866)[0;0m ERROR 09-05 15:50:32 [multiproc_executor.py:567]     from tbe.tik.api.tik_build import Tik
[1;36m(EngineCore_0 pid=285866)[0;0m ERROR 09-05 15:50:32 [multiproc_executor.py:567]   File "/usr/local/Ascend/ascend-toolkit/latest/python/site-packages/tbe/tik/__init__.py", line 53, in <module>
[1;36m(EngineCore_0 pid=285866)[0;0m ERROR 09-05 15:50:32 [multiproc_executor.py:567]     from tbe.tik.api.tik_build import Tik
[1;36m(EngineCore_0 pid=285866)[0;0m ERROR 09-05 15:50:32 [multiproc_executor.py:567]   File "/usr/local/Ascend/ascend-toolkit/latest/python/site-packages/tbe/tik/api/tik_build.py", line 39, in <module>
[1;36m(EngineCore_0 pid=285866)[0;0m ERROR 09-05 15:50:32 [multiproc_executor.py:567]     from tbe.tik.tik_lib import Expr
[1;36m(EngineCore_0 pid=285866)[0;0m ERROR 09-05 15:50:32 [multiproc_executor.py:567]   File "/usr/local/Ascend/ascend-toolkit/latest/python/site-packages/tbe/tik/tik_lib/__init__.py", line 13, in <module>
[1;36m(EngineCore_0 pid=285866)[0;0m ERROR 09-05 15:50:32 [multiproc_executor.py:567]     from tbe.tik.tik_lib.tik_vector_api_ import TikVectorApi
[1;36m(EngineCore_0 pid=285866)[0;0m ERROR 09-05 15:50:32 [multiproc_executor.py:567]   File "/usr/local/Ascend/ascend-toolkit/latest/python/site-packages/tbe/tik/tik_lib/tik_vector_api_.py", line 17, in <module>
[1;36m(EngineCore_0 pid=285866)[0;0m ERROR 09-05 15:50:32 [multiproc_executor.py:567]     from tbe.tik.api.tik_tensor import Tensor
[1;36m(EngineCore_0 pid=285866)[0;0m ERROR 09-05 15:50:32 [multiproc_executor.py:567]   File "/usr/local/Ascend/ascend-toolkit/latest/python/site-packages/tbe/tik/api/tik_tensor.py", line 26, in <module>
[1;36m(EngineCore_0 pid=285866)[0;0m ERROR 09-05 15:50:32 [multiproc_executor.py:567]     from tbe.tik.api.tik_scalar import Scalar
[1;36m(EngineCore_0 pid=285866)[0;0m ERROR 09-05 15:50:32 [multiproc_executor.py:567]   File "/usr/local/Ascend/ascend-toolkit/latest/python/site-packages/tbe/tik/api/tik_scalar.py", line 20, in <module>
[1;36m(EngineCore_0 pid=285866)[0;0m ERROR 09-05 15:50:32 [multiproc_executor.py:567]     from tbe.tik.debug.decorators import scalar_register
[1;36m(EngineCore_0 pid=285866)[0;0m ERROR 09-05 15:50:32 [multiproc_executor.py:567]   File "/usr/local/Ascend/ascend-toolkit/latest/python/site-packages/tbe/tik/debug/__init__.py", line 51, in <module>
[1;36m(EngineCore_0 pid=285866)[0;0m ERROR 09-05 15:50:32 [multiproc_executor.py:567]     from tbe.tik.debug.tik_vector_ops_debug.tik_vector_debug import vec_single_elewise_func_dec_new
[1;36m(EngineCore_0 pid=285866)[0;0m ERROR 09-05 15:50:32 [multiproc_executor.py:567]   File "/usr/local/Ascend/ascend-toolkit/latest/python/site-packages/tbe/tik/debug/tik_vector_ops_debug/tik_vector_debug.py", line 22, in <module>
[1;36m(EngineCore_0 pid=285866)[0;0m ERROR 09-05 15:50:32 [multiproc_executor.py:567]     from tbe.tik.debug.tik_vector_ops_debug.tik_vector_compare_debug_ import NewVcmp
[1;36m(EngineCore_0 pid=285866)[0;0m ERROR 09-05 15:50:32 [multiproc_executor.py:567]   File "<frozen importlib._bootstrap>", line 1176, in _find_and_load
[1;36m(EngineCore_0 pid=285866)[0;0m ERROR 09-05 15:50:32 [multiproc_executor.py:567]   File "<frozen importlib._bootstrap>", line 1147, in _find_and_load_unlocked
[1;36m(EngineCore_0 pid=285866)[0;0m ERROR 09-05 15:50:32 [multiproc_executor.py:567]   File "<frozen importlib._bootstrap>", line 690, in _load_unlocked
[1;36m(EngineCore_0 pid=285866)[0;0m ERROR 09-05 15:50:32 [multiproc_executor.py:567]   File "<frozen importlib._bootstrap_external>", line 936, in exec_module
[1;36m(EngineCore_0 pid=285866)[0;0m ERROR 09-05 15:50:32 [multiproc_executor.py:567]   File "<frozen importlib._bootstrap_external>", line 1069, in get_code
[1;36m(EngineCore_0 pid=285866)[0;0m ERROR 09-05 15:50:32 [multiproc_executor.py:567]   File "<frozen importlib._bootstrap_external>", line 729, in _compile_bytecode
[1;36m(EngineCore_0 pid=285866)[0;0m ERROR 09-05 15:50:32 [multiproc_executor.py:567]   File "/home/vllm/vllm/v1/executor/multiproc_executor.py", line 508, in signal_handler
[1;36m(EngineCore_0 pid=285866)[0;0m ERROR 09-05 15:50:32 [multiproc_executor.py:567]     raise SystemExit()
[1;36m(EngineCore_0 pid=285866)[0;0m ERROR 09-05 15:50:32 [multiproc_executor.py:567] SystemExit
[1;36m(EngineCore_0 pid=285866)[0;0m ERROR 09-05 15:50:32 [multiproc_executor.py:567] ] 
[1;36m(EngineCore_0 pid=285866)[0;0m ERROR 09-05 15:50:32 [multiproc_executor.py:567]         Possible Cause: The Python Func/Method does not exist.
[1;36m(EngineCore_0 pid=285866)[0;0m ERROR 09-05 15:50:32 [multiproc_executor.py:567]         Solution: 1.Check that the spelling of the invoked function is correct or the Python dependency library is installed.
[1;36m(EngineCore_0 pid=285866)[0;0m ERROR 09-05 15:50:32 [multiproc_executor.py:567] 2.Set CANN environment variables.
[1;36m(EngineCore_0 pid=285866)[0;0m ERROR 09-05 15:50:32 [multiproc_executor.py:567] 3.Reinstall the CANN package.
[1;36m(EngineCore_0 pid=285866)[0;0m ERROR 09-05 15:50:32 [multiproc_executor.py:567]         TraceBack (most recent call last):
[1;36m(EngineCore_0 pid=285866)[0;0m ERROR 09-05 15:50:32 [multiproc_executor.py:567]         Failed to call function init_multi_process_env[FUNC:InitParallelCompilation][FILE:python_adapter_manager.cc][LINE:180]
[1;36m(EngineCore_0 pid=285866)[0;0m ERROR 09-05 15:50:32 [multiproc_executor.py:567]         Failed to initialize TeConfigInfo.
[1;36m(EngineCore_0 pid=285866)[0;0m ERROR 09-05 15:50:32 [multiproc_executor.py:567]         [GraphOpt][InitializeInner][InitTbeFunc] Failed to init tbe.[FUNC:InitializeTeFusion][FILE:tbe_op_store_adapter.cc][LINE:1921]
[1;36m(EngineCore_0 pid=285866)[0;0m ERROR 09-05 15:50:32 [multiproc_executor.py:567]         [GraphOpt][InitializeInner][InitTeFusion]: Failed to initialize TeFusion.[FUNC:InitializeInner][FILE:tbe_op_store_adapter.cc][LINE:1888]
[1;36m(EngineCore_0 pid=285866)[0;0m ERROR 09-05 15:50:32 [multiproc_executor.py:567]         [SubGraphOpt][PreCompileOp][InitAdapter] InitializeAdapter adapter [tbe_op_adapter] failed! Ret [4294967295][FUNC:InitializeAdapter][FILE:op_store_adapter_manager.cc][LINE:79]
[1;36m(EngineCore_0 pid=285866)[0;0m ERROR 09-05 15:50:32 [multiproc_executor.py:567]         [SubGraphOpt][PreCompileOp][Init] Initialize op store adapter failed, OpsStoreName[tbe-custom].[FUNC:Initialize][FILE:op_store_adapter_manager.cc][LINE:120]
[1;36m(EngineCore_0 pid=285866)[0;0m ERROR 09-05 15:50:32 [multiproc_executor.py:567]         [FusionMngr][Init] Op store adapter manager init failed.[FUNC:Initialize][FILE:fusion_manager.cc][LINE:115]
[1;36m(EngineCore_0 pid=285866)[0;0m ERROR 09-05 15:50:32 [multiproc_executor.py:567]         PluginManager InvokeAll failed.[FUNC:Initialize][FILE:ops_kernel_manager.cc][LINE:83]
[1;36m(EngineCore_0 pid=285866)[0;0m ERROR 09-05 15:50:32 [multiproc_executor.py:567]         OpsManager initialize failed.[FUNC:InnerInitialize][FILE:gelib.cc][LINE:239]
[1;36m(EngineCore_0 pid=285866)[0;0m ERROR 09-05 15:50:32 [multiproc_executor.py:567]         GELib::InnerInitialize failed.[FUNC:Initialize][FILE:gelib.cc][LINE:164]
[1;36m(EngineCore_0 pid=285866)[0;0m ERROR 09-05 15:50:32 [multiproc_executor.py:567]         GEInitialize failed.[FUNC:GEInitialize][FILE:ge_api.cc][LINE:382]
[1;36m(EngineCore_0 pid=285866)[0;0m ERROR 09-05 15:50:32 [multiproc_executor.py:567]         [Initialize][Ge]GEInitialize failed. ge result = 4294967295[FUNC:ReportCallError][FILE:log_inner.cpp][LINE:161]
[1;36m(EngineCore_0 pid=285866)[0;0m ERROR 09-05 15:50:32 [multiproc_executor.py:567]         [Init][Compiler]Init compiler failed[FUNC:ReportInnerError][FILE:log_inner.cpp][LINE:145]
[1;36m(EngineCore_0 pid=285866)[0;0m ERROR 09-05 15:50:32 [multiproc_executor.py:567]         [Set][Options]OpCompileProcessor init failed![FUNC:ReportInnerError][FILE:log_inner.cpp][LINE:145]
[1;36m(EngineCore_0 pid=285866)[0;0m ERROR 09-05 15:50:32 [multiproc_executor.py:567] 
[1;36m(EngineCore_0 pid=285866)[0;0m ERROR 09-05 15:50:35 [core.py:708] EngineCore failed to start.
[1;36m(EngineCore_0 pid=285866)[0;0m ERROR 09-05 15:50:35 [core.py:708] Traceback (most recent call last):
[1;36m(EngineCore_0 pid=285866)[0;0m ERROR 09-05 15:50:35 [core.py:708]   File "/home/vllm/vllm/v1/engine/core.py", line 699, in run_engine_core
[1;36m(EngineCore_0 pid=285866)[0;0m ERROR 09-05 15:50:35 [core.py:708]     engine_core = EngineCoreProc(*args, **kwargs)
[1;36m(EngineCore_0 pid=285866)[0;0m ERROR 09-05 15:50:35 [core.py:708]                   ^^^^^^^^^^^^^^^^^^^^^^^^^^^^^^^
[1;36m(EngineCore_0 pid=285866)[0;0m ERROR 09-05 15:50:35 [core.py:708]   File "/home/vllm/vllm/v1/engine/core.py", line 500, in __init__
[1;36m(EngineCore_0 pid=285866)[0;0m ERROR 09-05 15:50:35 [core.py:708]     super().__init__(vllm_config, executor_class, log_stats,
[1;36m(EngineCore_0 pid=285866)[0;0m ERROR 09-05 15:50:35 [core.py:708]   File "/home/vllm/vllm/v1/engine/core.py", line 80, in __init__
[1;36m(EngineCore_0 pid=285866)[0;0m ERROR 09-05 15:50:35 [core.py:708]     self.model_executor = executor_class(vllm_config)
[1;36m(EngineCore_0 pid=285866)[0;0m ERROR 09-05 15:50:35 [core.py:708]                           ^^^^^^^^^^^^^^^^^^^^^^^^^^^
[1;36m(EngineCore_0 pid=285866)[0;0m ERROR 09-05 15:50:35 [core.py:708]   File "/home/vllm/vllm/executor/executor_base.py", line 54, in __init__
[1;36m(EngineCore_0 pid=285866)[0;0m ERROR 09-05 15:50:35 [core.py:708]     self._init_executor()
[1;36m(EngineCore_0 pid=285866)[0;0m ERROR 09-05 15:50:35 [core.py:708]   File "/home/vllm/vllm/v1/executor/multiproc_executor.py", line 98, in _init_executor
[1;36m(EngineCore_0 pid=285866)[0;0m ERROR 09-05 15:50:35 [core.py:708]     self.workers = WorkerProc.wait_for_ready(unready_workers)
[1;36m(EngineCore_0 pid=285866)[0;0m ERROR 09-05 15:50:35 [core.py:708]                    ^^^^^^^^^^^^^^^^^^^^^^^^^^^^^^^^^^^^^^^^^^
[1;36m(EngineCore_0 pid=285866)[0;0m ERROR 09-05 15:50:35 [core.py:708]   File "/home/vllm/vllm/v1/executor/multiproc_executor.py", line 480, in wait_for_ready
[1;36m(EngineCore_0 pid=285866)[0;0m ERROR 09-05 15:50:35 [core.py:708]     raise e from None
[1;36m(EngineCore_0 pid=285866)[0;0m ERROR 09-05 15:50:35 [core.py:708] Exception: WorkerProc initialization failed due to an exception in a background process. See stack trace for root cause.
[ERROR] 2025-09-05-15:50:35 (PID:285594, Device:-1, RankID:-1) ERR99999 UNKNOWN applicaiton exception
